Workbook
Name MonthlyHours: #REF!

Sheet RFR Base Line
M1: 2025 - Q1 - Quarter | P1: 2025 - Q2 - Quarter | S1: Q1 Burn | T1: Q2 Burn | U1: H1 Burn
M2: =SUBTOTAL(9,M4:M1048576) -> #REF! | N2: =SUBTOTAL(9,N4:N1048576) -> #REF! | O2: =SUBTOTAL(9,O4:O1048576) -> #REF! | P2: =SUBTOTAL(9,P4:P1048576) -> #REF! | Q2: =SUBTOTAL(9,Q4:Q1048576) -> #REF! | R2: =SUBTOTAL(9,R4:R1048576) -> #REF! | S2: =SUBTOTAL(9,S4:S1048576) -> #REF! | T2: =SUBTOTAL(9,T4:T1048576) -> #REF! | U2: =SUBTOTAL(9,U4:U1048576) -> #REF!
A3: EmpID | B3: Name | C3: Location | D3: ACT/PCT | E3: Skill Set | F3: Verizon TQ ID | G3: Verizon TQ Description | H3: ESA ID | I3: ESA Description | J3: Department | K3: Hourly Rate ($) | L3: Monthly Rate ($) | M3: 45658 | N3: 45689 | O3: 45717 | P3: 45748 | Q3: 45778 | R3: 45809 | S3: Q1 Burn | T3: Q2 Forecasted Burn | U3: H1 Burn Total | V3: Comments
A4: =#REF! -> #REF! | B4: =#REF! -> #REF! | C4: =#REF! -> #REF! | D4: =#REF! -> #REF! | E4: Java Springboot Microservices SpringReactive | F4: VZGTTQ00009462 | G4: VCG Flex (Strategically Ready Offers) TQ4164 CTS | H4: 1000431127 | I4: Verizon- VCG Flex - Strategica | J4: ADM | K4: =#REF! -> #REF! | L4: =#REF! -> #REF! | M4: =#REF! -> #REF! | N4: =#REF! -> #REF! | O4: =#REF! -> #REF! | P4: =#REF! -> #REF! | Q4: =#REF! -> #REF! | R4: =#REF! -> #REF! | ... U4: =#REF! -> #REF!
A5: =#REF! -> #REF! | B5: =#REF! -> #REF! | C5: =#REF! -> #REF! | D5: =#REF! -> #REF! | E5: QA Analyst | F5: VZGTTQ00009462 | G5: VCG Flex (Strategically Ready Offers) TQ4164 CTS | H5: 1000431127 | I5: Verizon- VCG Flex - Strategica | J5: QEA | K5: =#REF! -> #REF! | L5: =#REF! -> #REF! | M5: =#REF! -> #REF! | N5: =#REF! -> #REF! | O5: =#REF! -> #REF! | P5: =#REF! -> #REF! | Q5: =#REF! -> #REF! | R5: =#REF! -> #REF! | ... U5: =#REF! -> #REF!
A6: =#REF! -> #REF! | B6: =#REF! -> #REF! | C6: =#REF! -> #REF! | D6: =#REF! -> #REF! | E6: QA Analyst | F6: VZGTTQ00009462 | G6: VCG Flex (Strategically Ready Offers) TQ4164 CTS | H6: 1000431127 | I6: Verizon- VCG Flex - Strategica | J6: QEA | K6: =#REF! -> #REF! | L6: =#REF! -> #REF! | M6: =#REF! -> #REF! | N6: =#REF! -> #REF! | O6: =#REF! -> #REF! | P6: =#REF! -> #REF! | Q6: =#REF! -> #REF! | R6: =#REF! -> #REF! | ... U6: =#REF! -> #REF!
A7: =#REF! -> #REF! | B7: =#REF! -> #REF! | C7: =#REF! -> #REF! | D7: =#REF! -> #REF! | E7: QA Analyst | F7: VZGTTQ00009462 | G7: VCG Flex (Strategically Ready Offers) TQ4164 CTS | H7: 1000431127 | I7: Verizon- VCG Flex - Strategica | J7: ADM | K7: =#REF! -> #REF! | L7: =#REF! -> #REF! | M7: =#REF! -> #REF! | N7: =#REF! -> #REF! | O7: =#REF! -> #REF! | P7: =#REF! -> #REF! | Q7: =#REF! -> #REF! | R7: =#REF! -> #REF! | ... U7: =#REF! -> #REF!
A8: =#REF! -> #REF! | B8: =#REF! -> #REF! | C8: =#REF! -> #REF! | D8: =#REF! -> #REF! | E8: =#REF! -> #REF! | F8: VZGTTQ00009462 | G8: VCG Flex (Strategically Ready Offers) TQ4164 CTS | H8: 1000431127 | I8: Verizon- VCG Flex - Strategica | J8: ADM | K8: =#REF! -> #REF! | L8: =#REF! -> #REF! | M8: =#REF! -> #REF! | N8: =#REF! -> #REF! | O8: =#REF! -> #REF! | P8: =#REF! -> #REF! | Q8: =#REF! -> #REF! | R8: =#REF! -> #REF! | ... U8: =#REF! -> #REF!
A9: =#REF! -> #REF! | B9: =#REF! -> #REF! | C9: =#REF! -> #REF! | D9: =#REF! -> #REF! | E9: =#REF! -> #REF! | F9: VZGTTQ00009462 | G9: VCG Flex (Strategically Ready Offers) TQ4164 CTS | H9: 1000431127 | I9: Verizon- VCG Flex - Strategica | J9: QEA | K9: =#REF! -> #REF! | L9: =#REF! -> #REF! | M9: =#REF! -> #REF! | N9: =#REF! -> #REF! | O9: =#REF! -> #REF! | P9: =#REF! -> #REF! | Q9: =#REF! -> #REF! | R9: =#REF! -> #REF! | ... U9: =#REF! -> #REF!
A10: =#REF! -> #REF! | B10: =#REF! -> #REF! | C10: =#REF! -> #REF! | D10: =#REF! -> #REF! | E10: =#REF! -> #REF! | F10: VZGTTQ00009462 | G10: VCG Flex (Strategically Ready Offers) TQ4164 CTS | H10: 1000431127 | I10: Verizon- VCG Flex - Strategica | J10: QEA | K10: =#REF! -> #REF! | L10: =#REF! -> #REF! | M10: =#REF! -> #REF! | N10: =#REF! -> #REF! | O10: =#REF! -> #REF! | P10: =#REF! -> #REF! | Q10: =#REF! -> #REF! | R10: =#REF! -> #REF! | ... U10: =#REF! -> #REF!
A11: =#REF! -> #REF! | B11: =#REF! -> #REF! | C11: =#REF! -> #REF! | D11: =#REF! -> #REF! | E11: =#REF! -> #REF! | F11: VZGTTQ00009462 | G11: VCG Flex (Strategically Ready Offers) TQ4164 CTS | H11: 1000431127 | I11: Verizon- VCG Flex - Strategica | J11: ADM | K11: =#REF! -> #REF! | L11: =#REF! -> #REF! | M11: =#REF! -> #REF! | N11: =#REF! -> #REF! | O11: =#REF! -> #REF! | P11: =#REF! -> #REF! | Q11: =#REF! -> #REF! | R11: =#REF! -> #REF! | ... U11: =#REF! -> #REF!
A12: =#REF! -> #REF! | B12: =#REF! -> #REF! | C12: =#REF! -> #REF! | D12: =#REF! -> #REF! | E12: =#REF! -> #REF! | F12: VZGTTQ00009462 | G12: VCG Flex (Strategically Ready Offers) TQ4164 CTS | H12: 1000431127 | I12: Verizon- VCG Flex - Strategica | J12: ADM | K12: =#REF! -> #REF! | L12: =#REF! -> #REF! | M12: =#REF! -> #REF! | N12: =#REF! -> #REF! | O12: =#REF! -> #REF! | P12: =#REF! -> #REF! | Q12: =#REF! -> #REF! | R12: =#REF! -> #REF! | ... U12: =#REF! -> #REF!
A13: =#REF! -> #REF! | B13: =#REF! -> #REF! | C13: =#REF! -> #REF! | D13: =#REF! -> #REF! | E13: =#REF! -> #REF! | F13: VZGTTQ00009462 | G13: VCG Flex (Strategically Ready Offers) TQ4164 CTS | H13: 1000431127 | I13: Verizon- VCG Flex - Strategica | J13: Pega | K13: =#REF! -> #REF! | L13: =#REF! -> #REF! | M13: =#REF! -> #REF! | N13: =#REF! -> #REF! | O13: =#REF! -> #REF! | P13: =#REF! -> #REF! | Q13: =#REF! -> #REF! | R13: =#REF! -> #REF! | ... U13: =#REF! -> #REF!
A14: =#REF! -> #REF! | B14: =#REF! -> #REF! | C14: =#REF! -> #REF! | D14: =#REF! -> #REF! | E14: =#REF! -> #REF! | F14: VZGTTQ00009462 | G14: VCG Flex (Strategically Ready Offers) TQ4164 CTS | H14: 1000431127 | I14: Verizon- VCG Flex - Strategica | J14: Pega | K14: =#REF! -> #REF! | L14: =#REF! -> #REF! | M14: =#REF! -> #REF! | N14: =#REF! -> #REF! | O14: =#REF! -> #REF! | P14: =#REF! -> #REF! | Q14: =#REF! -> #REF! | R14: =#REF! -> #REF! | ... V14: =#REF! -> #REF!
A15: =#REF! -> #REF! | B15: =#REF! -> #REF! | C15: =#REF! -> #REF! | D15: =#REF! -> #REF! | E15: =#REF! -> #REF! | F15: VZGTTQ00009462 | G15: VCG Flex (Strategically Ready Offers) TQ4164 CTS | H15: 1000431127 | I15: Verizon- VCG Flex - Strategica | J15: ADM | K15: =#REF! -> #REF! | L15: =#REF! -> #REF! | M15: =#REF! -> #REF! | N15: =#REF! -> #REF! | O15: =#REF! -> #REF! | P15: =#REF! -> #REF! | Q15: =#REF! -> #REF! | R15: =#REF! -> #REF! | ... U15: =#REF! -> #REF!
A16: =#REF! -> #REF! | B16: =#REF! -> #REF! | C16: =#REF! -> #REF! | D16: =#REF! -> #REF! | E16: =#REF! -> #REF! | F16: VZGTTQ00009462 | G16: VCG Flex (Strategically Ready Offers) TQ4164 CTS | H16: 1000431127 | I16: Verizon- VCG Flex - Strategica | J16: Pega | K16: =#REF! -> #REF! | L16: =#REF! -> #REF! | M16: =#REF! -> #REF! | N16: =#REF! -> #REF! | O16: =#REF! -> #REF! | P16: =#REF! -> #REF! | Q16: =#REF! -> #REF! | R16: =#REF! -> #REF! | ... U16: =#REF! -> #REF!
A17: =#REF! -> #REF! | B17: =#REF! -> #REF! | C17: =#REF! -> #REF! | D17: =#REF! -> #REF! | E17: =#REF! -> #REF! | F17: VZGTTQ00009462 | G17: VCG Flex (Strategically Ready Offers) TQ4164 CTS | H17: 1000431127 | I17: Verizon- VCG Flex - Strategica | J17: ADM | K17: =#REF! -> #REF! | L17: =#REF! -> #REF! | M17: =#REF! -> #REF! | N17: =#REF! -> #REF! | O17: =#REF! -> #REF! | P17: =#REF! -> #REF! | Q17: =#REF! -> #REF! | R17: =#REF! -> #REF! | ... V17: =#REF! -> #REF!
A18: =#REF! -> #REF! | B18: =#REF! -> #REF! | C18: =#REF! -> #REF! | D18: =#REF! -> #REF! | E18: =#REF! -> #REF! | F18: VZGTTQ00009462 | G18: VCG Flex (Strategically Ready Offers) TQ4164 CTS | H18: 1000410331 | I18: VDSI VCG ACT Consol Journey | J18: ADM | K18: =#REF! -> #REF! | L18: =#REF! -> #REF! | M18: =#REF! -> #REF! | N18: =#REF! -> #REF! | O18: =#REF! -> #REF! | P18: =#REF! -> #REF! | Q18: =#REF! -> #REF! | R18: =#REF! -> #REF! | ... V18: =#REF! -> #REF!
A19: =#REF! -> #REF! | B19: =#REF! -> #REF! | C19: =#REF! -> #REF! | D19: =#REF! -> #REF! | E19: =#REF! -> #REF! | F19: VZGTTQ00009462 | G19: VCG Flex (Strategically Ready Offers) TQ4164 CTS | H19: 1000431127 | I19: Verizon- VCG Flex - Strategica | J19: ADM | K19: =#REF! -> #REF! | L19: =#REF! -> #REF! | M19: =#REF! -> #REF! | N19: =#REF! -> #REF! | O19: =#REF! -> #REF! | P19: =#REF! -> #REF! | Q19: =#REF! -> #REF! | R19: =#REF! -> #REF! | ... U19: =#REF! -> #REF!
A20: =#REF! -> #REF! | B20: =#REF! -> #REF! | C20: =#REF! -> #REF! | D20: =#REF! -> #REF! | E20: =#REF! -> #REF! | F20: VZGTTQ00008473 | G20: VCG Flex 2024 (CPI_EPC_PRE_DEEPSHIKHA) TQ4164 CTS | H20: 1000416318 | I20: Verizon-VCG Flex CPI EPC TQ846 | J20: ADM | K20: =#REF! -> #REF! | L20: =#REF! -> #REF! | M20: =#REF! -> #REF! | N20: =#REF! -> #REF! | O20: =#REF! -> #REF! | P20: =#REF! -> #REF! | Q20: =#REF! -> #REF! | R20: =#REF! -> #REF! | ... U20: =#REF! -> #REF!
A21: =#REF! -> #REF! | B21: =#REF! -> #REF! | C21: =#REF! -> #REF! | D21: =#REF! -> #REF! | E21: =#REF! -> #REF! | F21: VZGTTQ00008473 | G21: VCG Flex 2024 (CPI_EPC_PRE_DEEPSHIKHA) TQ4164 CTS | H21: 1000416318 | I21: Verizon-VCG Flex CPI EPC TQ846 | J21: ADM | K21: =#REF! -> #REF! | L21: =#REF! -> #REF! | M21: =#REF! -> #REF! | N21: =#REF! -> #REF! | O21: =#REF! -> #REF! | P21: =#REF! -> #REF! | Q21: =#REF! -> #REF! | R21: =#REF! -> #REF! | ... U21: =#REF! -> #REF!
A22: =#REF! -> #REF! | B22: =#REF! -> #REF! | C22: =#REF! -> #REF! | D22: =#REF! -> #REF! | E22: =#REF! -> #REF! | F22: VZGTTQ00008473 | G22: VCG Flex 2024 (CPI_EPC_PRE_DEEPSHIKHA) TQ4164 CTS | H22: 1000416318 | I22: Verizon-VCG Flex CPI EPC TQ846 | J22: ADM | K22: =#REF! -> #REF! | L22: =#REF! -> #REF! | M22: =#REF! -> #REF! | N22: =#REF! -> #REF! | O22: =#REF! -> #REF! | P22: =#REF! -> #REF! | Q22: =#REF! -> #REF! | R22: =#REF! -> #REF! | ... U22: =#REF! -> #REF!
A23: =#REF! -> #REF! | B23: =#REF! -> #REF! | C23: =#REF! -> #REF! | D23: =#REF! -> #REF! | E23: =#REF! -> #REF! | F23: VZGTTQ00008473 | G23: VCG Flex 2024 (CPI_EPC_PRE_DEEPSHIKHA) TQ4164 CTS | H23: 1000416318 | I23: Verizon-VCG Flex CPI EPC TQ846 | J23: ADM | K23: =#REF! -> #REF! | L23: =#REF! -> #REF! | M23: =#REF! -> #REF! | N23: =#REF! -> #REF! | O23: =#REF! -> #REF! | P23: =#REF! -> #REF! | Q23: =#REF! -> #REF! | R23: =#REF! -> #REF! | ... U23: =#REF! -> #REF!
A24: =#REF! -> #REF! | B24: =#REF! -> #REF! | C24: =#REF! -> #REF! | D24: =#REF! -> #REF! | E24: =#REF! -> #REF! | F24: VZGTTQ00008473 | G24: VCG Flex 2024 (CPI_EPC_PRE_DEEPSHIKHA) TQ4164 CTS | H24: 1000416318 | I24: Verizon-VCG Flex CPI EPC TQ846 | J24: ADM | K24: =#REF! -> #REF! | L24: =#REF! -> #REF! | M24: =#REF! -> #REF! | N24: =#REF! -> #REF! | O24: =#REF! -> #REF! | P24: =#REF! -> #REF! | Q24: =#REF! -> #REF! | R24: =#REF! -> #REF! | ... U24: =#REF! -> #REF!
A25: =#REF! -> #REF! | B25: =#REF! -> #REF! | C25: =#REF! -> #REF! | D25: =#REF! -> #REF! | E25: =#REF! -> #REF! | F25: VZGTTQ00008473 | G25: VCG Flex 2024 (CPI_EPC_PRE_DEEPSHIKHA) TQ4164 CTS | H25: 1000416318 | I25: Verizon-VCG Flex CPI EPC TQ846 | J25: ADM | K25: =#REF! -> #REF! | L25: =#REF! -> #REF! | M25: =#REF! -> #REF! | N25: =#REF! -> #REF! | O25: =#REF! -> #REF! | P25: =#REF! -> #REF! | Q25: =#REF! -> #REF! | R25: =#REF! -> #REF! | ... U25: =#REF! -> #REF!
A26: =#REF! -> #REF! | B26: =#REF! -> #REF! | C26: =#REF! -> #REF! | D26: =#REF! -> #REF! | E26: =#REF! -> #REF! | F26: VZGTTQ00008473 | G26: VCG Flex 2024 (CPI_EPC_PRE_DEEPSHIKHA) TQ4164 CTS | H26: 1000416318 | I26: Verizon-VCG Flex CPI EPC TQ846 | J26: ADM | K26: =#REF! -> #REF! | L26: =#REF! -> #REF! | M26: =#REF! -> #REF! | N26: =#REF! -> #REF! | O26: =#REF! -> #REF! | P26: =#REF! -> #REF! | Q26: =#REF! -> #REF! | R26: =#REF! -> #REF! | ... U26: =#REF! -> #REF!
A27: =#REF! -> #REF! | B27: =#REF! -> #REF! | C27: =#REF! -> #REF! | D27: =#REF! -> #REF! | E27: =#REF! -> #REF! | F27: VZGTTQ00008473 | G27: VCG Flex 2024 (CPI_EPC_PRE_DEEPSHIKHA) TQ4164 CTS | H27: 1000416318 | I27: Verizon-VCG Flex CPI EPC TQ846 | J27: ADM | K27: =#REF! -> #REF! | L27: =#REF! -> #REF! | M27: =#REF! -> #REF! | N27: =#REF! -> #REF! | O27: =#REF! -> #REF! | P27: =#REF! -> #REF! | Q27: =#REF! -> #REF! | R27: =#REF! -> #REF! | ... U27: =#REF! -> #REF!
A28: =#REF! -> #REF! | B28: =#REF! -> #REF! | C28: =#REF! -> #REF! | D28: =#REF! -> #REF! | E28: =#REF! -> #REF! | F28: VZGTTQ00008473 | G28: VCG Flex 2024 (CPI_EPC_PRE_DEEPSHIKHA) TQ4164 CTS | H28: 1000416318 | I28: Verizon-VCG Flex CPI EPC TQ846 | J28: ADM | K28: =#REF! -> #REF! | L28: =#REF! -> #REF! | M28: =#REF! -> #REF! | N28: =#REF! -> #REF! | O28: =#REF! -> #REF! | P28: =#REF! -> #REF! | Q28: =#REF! -> #REF! | R28: =#REF! -> #REF! | ... U28: =#REF! -> #REF!
A29: =#REF! -> #REF! | B29: =#REF! -> #REF! | C29: =#REF! -> #REF! | D29: =#REF! -> #REF! | E29: =#REF! -> #REF! | F29: VZGTTQ00008473 | G29: VCG Flex 2024 (CPI_EPC_PRE_DEEPSHIKHA) TQ4164 CTS | H29: 1000416318 | I29: Verizon-VCG Flex CPI EPC TQ846 | J29: ADM | K29: =#REF! -> #REF! | L29: =#REF! -> #REF! | M29: =#REF! -> #REF! | N29: =#REF! -> #REF! | O29: =#REF! -> #REF! | P29: =#REF! -> #REF! | Q29: =#REF! -> #REF! | R29: =#REF! -> #REF! | ... U29: =#REF! -> #REF!
A30: =#REF! -> #REF! | B30: =#REF! -> #REF! | C30: =#REF! -> #REF! | D30: =#REF! -> #REF! | E30: =#REF! -> #REF! | F30: VZGTTQ00008473 | G30: VCG Flex 2024 (CPI_EPC_PRE_DEEPSHIKHA) TQ4164 CTS | H30: 1000416318 | I30: Verizon-VCG Flex CPI EPC TQ846 | J30: ADM | K30: =#REF! -> #REF! | L30: =#REF! -> #REF! | M30: =#REF! -> #REF! | N30: =#REF! -> #REF! | O30: =#REF! -> #REF! | P30: =#REF! -> #REF! | Q30: =#REF! -> #REF! | R30: =#REF! -> #REF! | ... U30: =#REF! -> #REF!
... A35: =#REF! -> #REF! | B35: =#REF! -> #REF! | C35: =#REF! -> #REF! | D35: =#REF! -> #REF! | E35: =#REF! -> #REF! | F35: VZGTTQ00008473 | G35: VCG Flex 2024 (CPI_EPC_PRE_DEEPSHIKHA) TQ4164 CTS | H35: 1000448527 | I35: Verizon-Value Strategic Fulfil | J35: IDE | K35: =#REF! -> #REF! | L35: =#REF! -> #REF! | M35: =#REF! -> #REF! | N35: =#REF! -> #REF! | O35: =#REF! -> #REF! | P35: =#REF! -> #REF! | Q35: =#REF! -> #REF! | R35: =#REF! -> #REF! | ... U35: =#REF! -> #REF!
A36: ='TQ12042-DB'!#REF! -> #REF! | B36: ='TQ12042-DB'!#REF! -> #REF! | C36: ='TQ12042-DB'!#REF! -> #REF! | D36: ='TQ12042-DB'!#REF! -> #REF! | E36: ='TQ12042-DB'!#REF! -> #REF! | F36: VZGTTQ00008351 | G36: VCG Flex 2024 (FPP) CTS TQ4164 | H36: 1000415076 | I36: Verizon-VCG Flex FPP TQ8351-JA | J36: QEA | K36: ='TQ12042-DB'!#REF! -> #REF! | L36: ='TQ12042-DB'!#REF! -> #REF! | M36: ='TQ12042-DB'!#REF! -> #REF! | N36: ='TQ12042-DB'!#REF! -> #REF! | O36: ='TQ12042-DB'!#REF! -> #REF! | P36: ='TQ12042-DB'!#REF! -> #REF! | Q36: ='TQ12042-DB'!#REF! -> #REF! | R36: ='TQ12042-DB'!#REF! -> #REF! | ... U36: ='TQ12042-DB'!#REF! -> #REF!
A37: ='TQ12042-DB'!#REF! -> #REF! | B37: ='TQ12042-DB'!#REF! -> #REF! | C37: ='TQ12042-DB'!#REF! -> #REF! | D37: ='TQ12042-DB'!#REF! -> #REF! | E37: ='TQ12042-DB'!#REF! -> #REF! | F37: VZGTTQ00008351 | G37: VCG Flex 2024 (FPP) CTS TQ4164 | H37: 1000415076 | I37: Verizon-VCG Flex FPP TQ8351-JA | J37: ADM | K37: ='TQ12042-DB'!#REF! -> #REF! | L37: ='TQ12042-DB'!#REF! -> #REF! | M37: ='TQ12042-DB'!#REF! -> #REF! | N37: ='TQ12042-DB'!#REF! -> #REF! | O37: ='TQ12042-DB'!#REF! -> #REF! | P37: ='TQ12042-DB'!#REF! -> #REF! | Q37: ='TQ12042-DB'!#REF! -> #REF! | R37: ='TQ12042-DB'!#REF! -> #REF! | ... U37: ='TQ12042-DB'!#REF! -> #REF!
A38: ='TQ12042-DB'!#REF! -> #REF! | B38: ='TQ12042-DB'!#REF! -> #REF! | C38: ='TQ12042-DB'!#REF! -> #REF! | D38: ='TQ12042-DB'!#REF! -> #REF! | E38: ='TQ12042-DB'!#REF! -> #REF! | F38: VZGTTQ00008351 | G38: VCG Flex 2024 (FPP) CTS TQ4164 | H38: 1000415076 | I38: Verizon-VCG Flex FPP TQ8351-JA | J38: ADM | K38: ='TQ12042-DB'!#REF! -> #REF! | L38: ='TQ12042-DB'!#REF! -> #REF! | M38: ='TQ12042-DB'!#REF! -> #REF! | N38: ='TQ12042-DB'!#REF! -> #REF! | O38: ='TQ12042-DB'!#REF! -> #REF! | P38: ='TQ12042-DB'!#REF! -> #REF! | Q38: ='TQ12042-DB'!#REF! -> #REF! | R38: ='TQ12042-DB'!#REF! -> #REF! | ... U38: ='TQ12042-DB'!#REF! -> #REF!
A39: ='TQ12042-DB'!#REF! -> #REF! | B39: ='TQ12042-DB'!#REF! -> #REF! | C39: ='TQ12042-DB'!#REF! -> #REF! | D39: ='TQ12042-DB'!#REF! -> #REF! | E39: ='TQ12042-DB'!#REF! -> #REF! | F39: VZGTTQ00008351 | G39: VCG Flex 2024 (FPP) CTS TQ4164 | H39: 1000415076 | I39: Verizon-VCG Flex FPP TQ8351-JA | J39: IDE | K39: ='TQ12042-DB'!#REF! -> #REF! | L39: ='TQ12042-DB'!#REF! -> #REF! | M39: ='TQ12042-DB'!#REF! -> #REF! | N39: ='TQ12042-DB'!#REF! -> #REF! | O39: ='TQ12042-DB'!#REF! -> #REF! | P39: ='TQ12042-DB'!#REF! -> #REF! | Q39: ='TQ12042-DB'!#REF! -> #REF! | R39: ='TQ12042-DB'!#REF! -> #REF! | ... U39: ='TQ12042-DB'!#REF! -> #REF!
A40: ='TQ12042-DB'!#REF! -> #REF! | B40: ='TQ12042-DB'!#REF! -> #REF! | C40: ='TQ12042-DB'!#REF! -> #REF! | D40: ='TQ12042-DB'!#REF! -> #REF! | E40: ='TQ12042-DB'!#REF! -> #REF! | F40: VZGTTQ00008351 | G40: VCG Flex 2024 (FPP) CTS TQ4164 | H40: 1000415076 | I40: Verizon-VCG Flex FPP TQ8351-JA | J40: IOT | K40: ='TQ12042-DB'!#REF! -> #REF! | L40: ='TQ12042-DB'!#REF! -> #REF! | M40: ='TQ12042-DB'!#REF! -> #REF! | N40: ='TQ12042-DB'!#REF! -> #REF! | O40: ='TQ12042-DB'!#REF! -> #REF! | P40: ='TQ12042-DB'!#REF! -> #REF! | Q40: ='TQ12042-DB'!#REF! -> #REF! | R40: ='TQ12042-DB'!#REF! -> #REF! | ... U40: ='TQ12042-DB'!#REF! -> #REF!
A41: ='TQ12042-DB'!#REF! -> #REF! | B41: ='TQ12042-DB'!#REF! -> #REF! | C41: ='TQ12042-DB'!#REF! -> #REF! | D41: ='TQ12042-DB'!#REF! -> #REF! | E41: ='TQ12042-DB'!#REF! -> #REF! | F41: VZGTTQ00008351 | G41: VCG Flex 2024 (FPP) CTS TQ4164 | H41: 1000415076 | I41: Verizon-VCG Flex FPP TQ8351-JA | J41: ADM | K41: ='TQ12042-DB'!#REF! -> #REF! | L41: ='TQ12042-DB'!#REF! -> #REF! | M41: ='TQ12042-DB'!#REF! -> #REF! | N41: ='TQ12042-DB'!#REF! -> #REF! | O41: ='TQ12042-DB'!#REF! -> #REF! | P41: ='TQ12042-DB'!#REF! -> #REF! | Q41: ='TQ12042-DB'!#REF! -> #REF! | R41: ='TQ12042-DB'!#REF! -> #REF! | ... U41: ='TQ12042-DB'!#REF! -> #REF!
A42: ='TQ12042-DB'!#REF! -> #REF! | B42: ='TQ12042-DB'!#REF! -> #REF! | C42: ='TQ12042-DB'!#REF! -> #REF! | D42: ='TQ12042-DB'!#REF! -> #REF! | E42: ='TQ12042-DB'!#REF! -> #REF! | F42: VZGTTQ00008351 | G42: VCG Flex 2024 (FPP) CTS TQ4164 | H42: 1000415076 | I42: Verizon-VCG Flex FPP TQ8351-JA | J42: ADM | K42: ='TQ12042-DB'!#REF! -> #REF! | L42: ='TQ12042-DB'!#REF! -> #REF! | M42: ='TQ12042-DB'!#REF! -> #REF! | N42: ='TQ12042-DB'!#REF! -> #REF! | O42: ='TQ12042-DB'!#REF! -> #REF! | P42: ='TQ12042-DB'!#REF! -> #REF! | Q42: ='TQ12042-DB'!#REF! -> #REF! | R42: ='TQ12042-DB'!#REF! -> #REF! | ... U42: ='TQ12042-DB'!#REF! -> #REF!
A43: ='TQ12042-DB'!#REF! -> #REF! | B43: ='TQ12042-DB'!#REF! -> #REF! | C43: ='TQ12042-DB'!#REF! -> #REF! | D43: ='TQ12042-DB'!#REF! -> #REF! | E43: ='TQ12042-DB'!#REF! -> #REF! | F43: VZGTTQ00008351 | G43: VCG Flex 2024 (FPP) CTS TQ4164 | H43: 1000415076 | I43: Verizon-VCG Flex FPP TQ8351-JA | J43: Pega | K43: ='TQ12042-DB'!#REF! -> #REF! | L43: ='TQ12042-DB'!#REF! -> #REF! | M43: ='TQ12042-DB'!#REF! -> #REF! | N43: ='TQ12042-DB'!#REF! -> #REF! | O43: ='TQ12042-DB'!#REF! -> #REF! | P43: ='TQ12042-DB'!#REF! -> #REF! | Q43: ='TQ12042-DB'!#REF! -> #REF! | R43: ='TQ12042-DB'!#REF! -> #REF! | ... U43: ='TQ12042-DB'!#REF! -> #REF!
A44: ='TQ12042-DB'!#REF! -> #REF! | B44: ='TQ12042-DB'!#REF! -> #REF! | C44: ='TQ12042-DB'!#REF! -> #REF! | D44: ='TQ12042-DB'!#REF! -> #REF! | E44: ='TQ12042-DB'!#REF! -> #REF! | F44: VZGTTQ00008351 | G44: VCG Flex 2024 (FPP) CTS TQ4164 | H44: 1000415076 | I44: Verizon-VCG Flex FPP TQ8351-JA | J44: ADM | K44: ='TQ12042-DB'!#REF! -> #REF! | L44: ='TQ12042-DB'!#REF! -> #REF! | M44: ='TQ12042-DB'!#REF! -> #REF! | N44: ='TQ12042-DB'!#REF! -> #REF! | O44: ='TQ12042-DB'!#REF! -> #REF! | P44: ='TQ12042-DB'!#REF! -> #REF! | Q44: ='TQ12042-DB'!#REF! -> #REF! | R44: ='TQ12042-DB'!#REF! -> #REF! | ... U44: ='TQ12042-DB'!#REF! -> #REF!
...

Sheet Legend
A1: Flex | B1: Old Project ID | C1: Old Project Name | D1: New Flex 2.0 ESA ID | E1: New Flex 2.0 ESA Project Description | F1: Verizon Sr.D name | G1: Old Verizon TQ | H1: Old SOW | I1: Old Verizon TQ Descroption | J1: New TQ ID | K1: New SOW | L1: New Verizon TQ Descroption | M1: Tower Lead
A2: Global SOW | B2: 1000445090 | C2: Verizon-VCG H&M Tanglewood-JAN | D2: 1000456940 | E2: Verizon-VCG HM Flex2.0 Tanglew | F2: Apurava Sheth | G2: VZGTTQ00010318 | H2: Old SOW | I2: VCG Flex (Tanglewood) TQ4164 CTS | J2: VZGTTQ00011832 | K2: New SOW | L2: VCG Flex (Tanglewood) CTS TQ9703 | M2: Arun Jayaprakash
A3: Global SOW | B3: 1000410706 | C3: Verizon-VCG H&M Flex ACT 5G Pr | D3: 1000456928 | E3: Verizon-VCG HM Flex2.0 5G | F3: Apurava Sheth | G3: VZGTTQ00008385 | H3: Old SOW | I3: VCG Flex 2024 (5G FWA Consumer Products) TQ4164 CTS | J3: VZGTTQ00011596 | K3: New SOW | L3: VCG Flex (5G FWA Consumer Products) TQ9703 CTS | M3: Arun Jayaprakash
A4: Global SOW | B4: 1000410707 | C4: Verizon-VCG H&M Flex ACT Dig H | D4: 1000456930 | E4: Verizon-VCG HM Flex2.0 Dig Hom | F4: Apurava Sheth | G4: VZGTTQ00008947 | H4: Old SOW | I4: VCG Flex (Home App) TQ4164 CTS | J4: VZGTTQ00011409 | K4: New SOW | L4: VCG Flex (5G FWA Digital Experience) TQ4164 CTS - 2025 | M4: Arun Jayaprakash
D5: 1000460544 | E5: Verizon-VCG Flex 2.0 Home App- | F5: Apurava Sheth | J5: VZGTTQ00011434 | K5: New SOW | L5: VCG Flex (Home App) TQ4164 CTS - 2025 | M5: Arun Jayaprakash
A6: Global SOW | B6: 1000412773 | C6: Verizon-VCG H&M Flex Mobile Of | D6: 1000456932 | E6: Verizon-VCG HM Flex 2.0 Mobile | F6: Brian Hurd | G6: VZGTTQ00008730 | H6: Old SOW | I6: VCG Flex (Mobile Offers Post Paid) TQ4164 CTS | J6: VZGTTQ00011797 | K6: New SOW | L6: VCG Flex (Mobile Offers Post Paid) TQ9703 CTS | M6: Vijay Vadalmudi
A7: Global SOW | B7: 1000416318 | C7: Verizon-VCG H&M Flex CPI EPC T | D7: 1000456939 | E7: Verizon-VCG HM Flex2.0 CPI EPC | F7: Deepshikha Bansal | G7: VZGTTQ00008473 | H7: Old SOW | I7: VCG Flex 2024 (CPI_EPC_PRE_DEEPSHIKHA) TQ4164 CTS | J7: VZGTTQ00011503 | K7: New SOW | L7: VCG Flex 2024 (CPI_EPC_PRE_DEEPSHIKHA) TQ4164 CTS - 2025 | M7: Parthiban Ilango
A8: Global SOW | B8: 1000430852 | C8: Verizon-VCG H&M Federated inno | D8: 1000430852 | E8: Verizon-VCG H&M Federated inno | F8: Deepshikha Bansal | G8: VZGTTQ00009511 | H8: Old SOW | I8: VCG Flex (Innovation - Federated Catalog) TQ4164 CTS | J8: VZGTTQ00009511 | K8: New SOW | L8: VCG Flex (Innovation - Federated Catalog) TQ4164 CTS | M8: Parthiban Ilango
A9: Global SOW | B9: 1000431127 | C9: Verizon- VCG H&M Flex - Strate | D9: 1000459566 | E9: Verizon VCG Flex 2.0 HM Strate | F9: Deepshikha Bansal | G9: VZGTTQ00009462 | H9: Old SOW | I9: VCG Flex (Strategically Ready Offers) TQ4164 CTS | J9: VZGTTQ00012012 | K9: New SOW | L9: VCG Flex (Strategically Ready Offers) TQ9703 CTS | M9: Parthiban Ilango
A10: Global SOW | B10: 1000454900 | C10: Verizon-VCG HM OEM-Invoicing-J | D10: 1000454900 | E10: Verizon-VCG HM OEM-Invoicing-J | F10: Deepshikha Bansal | G10: VZGTTQ00011403 | H10: Old SOW | I10: VCG Flex (OEM Invoicing) TQ4164 CTS | J10: VZGTTQ00011403 | K10: New SOW | L10: VCG Flex (OEM Invoicing) TQ4164 CTS | M10: Parthiban Ilango
A11: Global SOW | B11: 1000415076 | C11: Verizon-VCG H&M Flex FPP TQ835 | D11: 1000459568 | E11: Verizon-VCG H&M Flex 2.0 FPP- | F11: Deepshikha Bansal | G11: VZGTTQ00008351 | H11: Old SOW | I11: VCG Flex 2024 (FPP) CTS TQ4164 | J11: VZGTTQ00012042 | K11: New SOW | L11: VCG Flex 2024 (FPP) CTS TQ4164 | M11: Parthiban Ilango
A12: Global SOW | B12: 1000451136 | C12: Verizon-VCG H&M Contract Trans | D12: 1000456941 | E12: Verizon-VCG HM Flex2.0 Contrac | F12: Deepshikha Bansal | G12: VZGTTQ00011059 | H12: Old SOW | I12: VCG Flex (XCIO VBG CBRO) CTS TQ4164 | J12: VZGTTQ00012094 | K12: New SOW | L12: VCG Flex (XCIO VBG CBRO) CTS TQ4164 | M12: Parthiban Ilango
A13: Global SOW | B13: 1000447309 | C13: Verizon-VCG Maslov inst CMS HM | D13: 1000459572 | E13: Verizon-VCG Flex2.0 Maslov ins | F13: Deepshikha Bansal | G13: VZGTTQ00011829 | H13: Old SOW | I13: VCG Flex (Maslow) CTS TQ9703 | J13: VZGTTQ00011829 | K13: New SOW | L13: VCG Flex (Maslow) CTS TQ9703 | M13: Parthiban Ilango
A14: Global SOW | B14: 1000422748 | C14: Verizon-VCG H&M Flex Commissio | D14: 1000456890 | E14: Verizon-VCG HM Flex2.0 Commiss | F14: Harsha Dave | G14: VZGTTQ00008929 | H14: Old SOW | I14: VCG Flex (Commissions) TQ4164 CTS | J14: VZGTTQ00011825 | K14: New SOW | L14: VCG Flex (Sales Performance and commission operations) TQ9703 CTS | M14: Arun Jayaprakash
A15: Global SOW | B15: 1000445724 | C15: Verizon-VCG Flex Sales Perf Ex | D15: 1000456890 | E15: VCG Flex (Sales Performance and commission) TQ4164 CTS | F15: Harsha Dave | G15: VZGTTQ00010436 | H15: Old SOW | I15: VCG Flex (Commissions) TQ4164 CTS | J15: VZGTTQ00011825 | K15: New SOW | L15: VCG Flex (Sales Performance and commission operations) TQ9703 CTS | M15: Arun Jayaprakash
A16: Global SOW | B16: 1000417402 | C16: Verizon-VCG H&M Flex Elvis HM | D16: 1000459563 | E16: Verizon-VCG Flex 2.0 HM Elvis | F16: Rama Achan | G16: VZGTTQ00009564 | H16: Old SOW | I16: VCG Flex (Project Elvis) TQ4164 CTS | J16: VZGTTQ00011460 | K16: New SOW | L16: VCG Flex (Project Elvis) TQ4164 CTS - 2025 | M16: Kali Prasad
A17: Global SOW | B17: 1000417403 | C17: Verizon-VCG H&M Flex DigiOps - | D17: 1000456926 | E17: Verizon-VCG HM Flex2.0 Digiops Business | F17: Umar Mujeeb | G17: VZGTTQ00008593 | H17: Old SOW | I17: VCG Flex (Digital Ops Enabler) TQ4164 CTS | J17: VZGTTQ00011597 | K17: New SOW | L17: VCG Flex (Digital Ops Enabler) TQ4164 CTS - 2025 | M17: Kali Prasad
... A19: Global SOW | B19: 1000455006 | C19: Verizon-VCG HM Marketing Base | D19: 1000456949 | E19: Verizon-VCG HM Flex2.0 Marktng | F19: Umar Mujeeb | G19: VZGTTQ00011151 | H19: Old SOW | I19: VCG Flex (Marketing Base Personalization) TQ4164 CTS | J19: VZGTTQ00011917 | K19: New SOW | L19: VCG Flex (Marketing Base Personalization) TQ9703 CTS | M19: Kali Prasad
A20: Global SOW | D20: 1000440471 | E20: Verizon-VCG Flex S&P Enterpris | J20: VZGTTQ00010502 | K20: New SOW | L20: TSGI Flex - VCG Solution Architecture SOW with Cognizant - Ravi Thomare | M20: Dipanakr Roy
A21: Global SOW | D21: 1000449935 | E21: Verizon-VCG CVR Equifax-APR 20 | J21: VZGTTQ00010960 | K21: New SOW | L21: Flex VCG-CTS - ELEU Equifax Verification - VZGTTQ00010109 | M21: Dipanakr Roy
A22: India SOW | D22: 1000458633 | E22: VDSI-Flex-H&M-Base Marketing | F22: Mangala Seetharaman | J22: VZGTTQ00011931 | K22: New SOW | L22: VCG VZI_Base Marketing_CTS_Sai | M22: Kali Prasad
A23: India SOW | D23: 1000458648 | E23: VDSI-Flex-H&M-Unified communications & Pega QA | F23: Mangala Seetharaman | J23: VZGTTQ00011913 | K23: New SOW | L23: VCG VZI_Unified communications & Pega QA_CTS_Amjad | M23: Kali Prasad
A24: India SOW | D24: 1000458649 | E24: VDSI-Flex-H&M-Marketing Products & Platforms | F24: Mangala Seetharaman | J24: VZGTTQ00011836 | K24: New SOW | L24: VCG VZI_Device & Accessory/ Consumer Products/ MarketingAutomation_CTS_Arun | M24: Ranjith
A25: India SOW | D25: 1000458637 | E25: VDSI-Flex-H&M-Plans ,Perks & Service Offers | F25: Mangala Seetharaman | J25: VZGTTQ00011938 | K25: New SOW | L25: VCG VZI_Plans ,Perks& Service Offers_CTS_Samta | M25: Srini K
A26: India SOW | D26: 1000458636 | E26: VDSI-Flex-H&M-Consumer Products | F26: Robert Sunderdas | J26: VZGTTQ00011861 | K26: New SOW | L26: VCG VZI_Consumer Products_CTS_Harini | M26: Suneeta Kolla / Arun Jayaprakash
A27: India SOW | D27: 1000458645 | E27: VDSI-Flex-H&M-Digital CX | F27: Robert Sunderdas | J27: VZGTTQ00012147 | K27: New SOW | L27: VCG VZI_Digital CX_CTS_Harini | M27: Suneeta Kolla / Arun Jayaprakash
A28: India SOW | D28: 1000458868 | E28: VDSI-Flex-H&M-Compensation & Ops | F28: Robert Sunderdas | J28: VZGTTQ00011944 | K28: New SOW | L28: VCG VZI_Customer service ops_CTS_Harini | M28: Suneeta Kolla / Arun Jayaprakash
A29: India SOW | D29: 1000458647 | E29: VDSI-Flex-H&M- Customer Service Ops | F29: Robert Sunderdas | J29: VZGTTQ00011932 | K29: New SOW | L29: VCG VZI_ Customer service ops-Leads_CTS_Harini | M29: Suneeta Kolla / Arun Jayaprakash
A30: India SOW | D30: 1000458654 | E30: VDSI-Flex-H&M-Vision SOR Platforms- SCM Apps | F30: Robert Sunderdas | J30: VZGTTQ00011950 | K30: New SOW | L30: VCG VZI_Vision SOR Platforms- SCM Apps_CTS_Anand | M30: Kali Prasad
A31: India SOW | D31: 1000458651 | E31: VDSI-Flex-H&M-Vision SOR Platforms - IFE BCP | F31: Robert Sunderdas | J31: VZGTTQ00011840 | K31: New SOW | L31: VCG VZI_Vision SOR Platforms_CTS_Anand | M31: Kali Prasad
A32: Global SOW | D32: 1000456935 | E32: Verizon-VCG HM Flex 2.0 Compli | M32: Dipanakr Roy
A33: Global SOW | D33: 1000458009 | E33: Verizon-VCG HM TQ11465-VBG NSA | F33: Deepshikha Bansal | J33: VZGTTQ00011465 | K33: New SOW | L33: VCG Flex (VBG NSA Deepshikha) TQ4164 CTS | M33: Parthiban Ilango
A34: Global SOW | D34: 1000462526 | E34: Verizon-VCG H&M Churn Base Mar | F34: Umar Mujeeb | J34: VZGTTQ00012148 | K34: New SOW | L34: VCG Flex (Base Marketing Churn)TQ9703 CTS | M34: Kali Prasad
A35: Global SOW | D35: 1000462570 | E35: Verizon-NBX Opportunity H&M-AU | F35: Umar Mujeeb | M35: Kali Prasad
D36: 1000467271 | E36: VDSI-Flex-H&M-Turing_AI | F36: Mangala Seetharaman | M36: Kali Prasad
M1048576: Arun Jayaprakash

Sheet H&M May RFR
A1: 45778 | B1: Home and Marketing,SOR - May RFR
A2: Cognizant Project ID | B2: Cognizant Project Descriptiom | C2: Verizon Project ID (TQ ID) | D2: Verizon Project Description | E2: ESA Manager | F2: ADM | G2: Adobe | H2: AIA | I2: CIS | J2: IDE | K2: IOA | L2: IOT | M2: Pega | N2: QEA | O2: Vertical Core | P2: Grand Total | R2: ADM | S2: Adobe | T2: AIA | U2: CIS | V2: IDE | W2: IOA | X2: IOT | Y2: Pega | Z2: QEA | AA2: Vertical Core | AB2: Grand Total
A3: 1000348365 | B3: VDSI-VCG H&M 1Messaging and Co | C3: VZGTTQ00005360 | D3: ONE MESSAGE AND COMPENSATION APPLICATIONS DEVELOPMENT | E3: Ramasamy,Ravisankar | F3: 57378.146 | G3: 18823.415 | H3: 0 | J3: 0 | K3: 0 | N3: 0 | P3: =SUM(F3:O3) -> 76201.561 | R3: =F3/$P3 -> 0.75297862 | S3: =G3/$P3 -> 0.24702138 | T3: =H3/$P3 -> 0 | U3: =I3/$P3 -> 0 | V3: =J3/$P3 -> 0 | W3: =K3/$P3 -> 0 | X3: =L3/$P3 -> 0 | Y3: =M3/$P3 -> 0 | ... AA3: =O3/$P3 -> 0 | AB3: =SUM(R3:AA3) -> 1
A4: 1000415076 | B4: Verizon-VCG H&M Flex FPP TQ835 | C4: VZGTTQ00008351 | D4: VCG Flex 2024 (FPP) CTS TQ4164 | E4: Ilango,Parthiban | F4: 49392 | J4: 4200 | L4: 16296 | M4: 57288 | N4: 12600 | P4: =SUM(F4:O4) -> 139776 | R4: =F4/$P4 -> 0.35336538 | S4: =G4/$P4 -> 0 | T4: =H4/$P4 -> 0 | U4: =I4/$P4 -> 0 | V4: =J4/$P4 -> 0.030048077 | W4: =K4/$P4 -> 0 | X4: =L4/$P4 -> 0.11658654 | Y4: =M4/$P4 -> 0.40985577 | ... AA4: =O4/$P4 -> 0 | AB4: =SUM(R4:AA4) -> 1
A5: 1000410707 | B5: Verizon-VCG H&M Flex ACT Dig H | C5: VZGTTQ00008374 | D5: VCG Flex (5G FWA Digital Experience) TQ4164 CTS | E5: Jayaprakash,Arun Kumar | F5: 36960 | J5: 17640 | N5: 16800 | P5: =SUM(F5:O5) -> 71400 | R5: =F5/$P5 -> 0.51764706 | S5: =G5/$P5 -> 0 | T5: =H5/$P5 -> 0 | U5: =I5/$P5 -> 0 | V5: =J5/$P5 -> 0.24705882 | W5: =K5/$P5 -> 0 | X5: =L5/$P5 -> 0 | Y5: =M5/$P5 -> 0 | ... AA5: =O5/$P5 -> 0 | AB5: =SUM(R5:AA5) -> 1
A6: 1000410706 | B6: Verizon-VCG H&M Flex ACT 5G Pr | C6: VZGTTQ00008385 | D6: VCG Flex 2024 (5G FWA Consumer Products) TQ4164 CTS | E6: Mylapore Somasekhar,Jeyakumaar | F6: 81480 | J6: 33600 | M6: 0 | N6: 0 | P6: =SUM(F6:O6) -> 115080 | R6: =F6/$P6 -> 0.7080292 | S6: =G6/$P6 -> 0 | T6: =H6/$P6 -> 0 | U6: =I6/$P6 -> 0 | V6: =J6/$P6 -> 0.2919708 | W6: =K6/$P6 -> 0 | X6: =L6/$P6 -> 0 | Y6: =M6/$P6 -> 0 | ... AA6: =O6/$P6 -> 0 | AB6: =SUM(R6:AA6) -> 1
A7: 1000416318 | B7: Verizon-VCG H&M Flex CPI EPC T | C7: VZGTTQ00008473 | D7: VCG Flex 2024 (CPI_EPC_PRE_DEEPSHIKHA) TQ4164 CTS | E7: Ilango,Parthiban | F7: 229656 | J7: 16296 | P7: =SUM(F7:O7) -> 245952 | R7: =F7/$P7 -> 0.93374317 | S7: =G7/$P7 -> 0 | T7: =H7/$P7 -> 0 | U7: =I7/$P7 -> 0 | V7: =J7/$P7 -> 0.066256831 | W7: =K7/$P7 -> 0 | X7: =L7/$P7 -> 0 | Y7: =M7/$P7 -> 0 | ... AA7: =O7/$P7 -> 0 | AB7: =SUM(R7:AA7) -> 1
A8: 1000417403 | B8: Verizon-VCG H&M Flex DigiOps - | C8: VZGTTQ00008593 | D8: VCG Flex (Digital Ops Enabler) TQ4164 CTS | E8: Jain,Atik | F8: 0 | G8: 42000 | N8: 0 | P8: =SUM(F8:O8) -> 42000 | R8: =F8/$P8 -> 0 | S8: =G8/$P8 -> 1 | T8: =H8/$P8 -> 0 | U8: =I8/$P8 -> 0 | V8: =J8/$P8 -> 0 | W8: =K8/$P8 -> 0 | X8: =L8/$P8 -> 0 | Y8: =M8/$P8 -> 0 | ... AA8: =O8/$P8 -> 0 | AB8: =SUM(R8:AA8) -> 1
A9: 1000412773 | B9: Verizon-VCG H&M Flex Mobile Of | C9: VZGTTQ00008730 | D9: VCG Flex (Mobile Offers Post Paid) TQ4164 CTS | E9: Vadlamudi,Vijay Kumar | F9: 425712 | J9: 192528 | K9: 3696 | L9: 48552 | M9: 133056 | N9: 50400 | P9: =SUM(F9:O9) -> 853944 | R9: =F9/$P9 -> 0.49852449 | S9: =G9/$P9 -> 0 | T9: =H9/$P9 -> 0 | U9: =I9/$P9 -> 0 | V9: =J9/$P9 -> 0.22545741 | W9: =K9/$P9 -> 0.0043281527 | X9: =L9/$P9 -> 0.056856187 | Y9: =M9/$P9 -> 0.1558135 | ... AA9: =O9/$P9 -> 0 | AB9: =SUM(R9:AA9) -> 1
A10: 1000422748 | B10: Verizon-VCG H&M Flex Commissio | C10: VZGTTQ00008929 | D10: VCG Flex (Commissions) TQ4164 CTS | E10: Singh,Shweta | F10: 101160 | H10: 6256 | P10: =SUM(F10:O10) -> 107416 | R10: =F10/$P10 -> 0.94175914 | S10: =G10/$P10 -> 0 | T10: =H10/$P10 -> 0.058240858 | U10: =I10/$P10 -> 0 | V10: =J10/$P10 -> 0 | W10: =K10/$P10 -> 0 | X10: =L10/$P10 -> 0 | Y10: =M10/$P10 -> 0 | ... AA10: =O10/$P10 -> 0 | AB10: =SUM(R10:AA10) -> 1
A11: 1000422753 | B11: Verizon-VCG H&M Flex Home APP | C11: VZGTTQ00008947 | D11: VCG Flex (Home App) TQ4164 CTS | E11: Mylapore Somasekhar,Jeyakumaar | F11: 15960 | J11: 0 | M11: 19320 | N11: 30576 | P11: =SUM(F11:O11) -> 65856 | R11: =F11/$P11 -> 0.24234694 | S11: =G11/$P11 -> 0 | T11: =H11/$P11 -> 0 | U11: =I11/$P11 -> 0 | V11: =J11/$P11 -> 0 | W11: =K11/$P11 -> 0 | X11: =L11/$P11 -> 0 | Y11: =M11/$P11 -> 0.29336735 | ... AA11: =O11/$P11 -> 0 | AB11: =SUM(R11:AA11) -> 1
A12: 1000416320 | B12: Verizon-VCG H&M Flex oneMessag | C12: VZGTTQ00009022 | D12: VCG Flex (VBG One Message AEM Migration) TQ4164 CTS | E12: Chennam,Sujana Sree | F12: 105000 | M12: 16296 | N12: 12600 | P12: =SUM(F12:O12) -> 133896 | R12: =F12/$P12 -> 0.78419072 | S12: =G12/$P12 -> 0 | T12: =H12/$P12 -> 0 | U12: =I12/$P12 -> 0 | V12: =J12/$P12 -> 0 | W12: =K12/$P12 -> 0 | X12: =L12/$P12 -> 0 | Y12: =M12/$P12 -> 0.1217064 | ... AA12: =O12/$P12 -> 0 | AB12: =SUM(R12:AA12) -> 1
A13: 1000425394 | B13: VDSI VCG H&M Knowledge Orchest | C13: VZGTTQ00009155 | D13: VCG Knowledge Orchestration | E13: Thangavadivel,Sharathkumar | F13: 7572.2927 | G13: 21083.512 | N13: 7108.6829 | P13: =SUM(F13:O13) -> 35764.488 | R13: =F13/$P13 -> 0.21172658 | S13: =G13/$P13 -> 0.58950969 | T13: =H13/$P13 -> 0 | U13: =I13/$P13 -> 0 | V13: =J13/$P13 -> 0 | W13: =K13/$P13 -> 0 | X13: =L13/$P13 -> 0 | Y13: =M13/$P13 -> 0 | ... AA13: =O13/$P13 -> 0 | AB13: =SUM(R13:AA13) -> 1
A14: 1000425175 | B14: VDSI VCG H&M IFE and BCP | C14: VZGTTQ00009158 | D14: VCG IFE and BCP | E14: P,Arunkumar | F14: 22328.39 | J14: 20744.39 | P14: =SUM(F14:O14) -> 43072.78 | R14: =F14/$P14 -> 0.51838748 | S14: =G14/$P14 -> 0 | T14: =H14/$P14 -> 0 | U14: =I14/$P14 -> 0 | V14: =J14/$P14 -> 0.48161252 | W14: =K14/$P14 -> 0 | X14: =L14/$P14 -> 0 | Y14: =M14/$P14 -> 0 | ... AA14: =O14/$P14 -> 0 | AB14: =SUM(R14:AA14) -> 1
A15: 1000428977 | B15: VDSI-VCG H&M 5G Home Network | C15: VZGTTQ00009363 | D15: VCG_5G Products, Home Network and Platform | E15: Periyakaruppan,Kannan | F15: 81642.537 | H15: 16524.683 | I15: 3786.1463 | J15: 75879.61 | K15: 0 | M15: 8817.1707 | N15: 74439.415 | P15: =SUM(F15:O15) -> 261089.56 | R15: =F15/$P15 -> 0.31269935 | S15: =G15/$P15 -> 0 | T15: =H15/$P15 -> 0.063291243 | U15: =I15/$P15 -> 0.014501332 | V15: =J15/$P15 -> 0.29062675 | W15: =K15/$P15 -> 0 | X15: =L15/$P15 -> 0 | Y15: =M15/$P15 -> 0.033770675 | ... AA15: =O15/$P15 -> 0 | AB15: =SUM(R15:AA15) -> 1
A16: 1000428976 | B16: VDSI-VCG H&M 5G Home-Tanglewoo | C16: VZGTTQ00009364 | D16: VCG_5G Products and Tanglewood | E16: Periyakaruppan,Kannan | F16: 14442.732 | J16: 127872.59 | K16: 23513.171 | M16: 30810.732 | N16: 65987.122 | P16: =SUM(F16:O16) -> 262626.34 | R16: =F16/$P16 -> 0.054993462 | S16: =G16/$P16 -> 0 | T16: =H16/$P16 -> 0 | U16: =I16/$P16 -> 0 | V16: =J16/$P16 -> 0.48689931 | W16: =K16/$P16 -> 0.089530892 | X16: =L16/$P16 -> 0 | Y16: =M16/$P16 -> 0.11731775 | ... AA16: =O16/$P16 -> 0 | AB16: =SUM(R16:AA16) -> 1
A17: 1000430236 | B17: VDSI-VCG-H&M-Home-FWA | C17: VZGTTQ00009371 | D17: VDSI-VCG-H&M-Home-FWA | E17: Kalyanasundaram,Srinivasan | F17: 25699.52 | G17: 3109.92 | J17: 69222.56 | K17: 7626.08 | M17: 24640 | N17: 43428 | O17: 4408.8 | P17: =SUM(F17:O17) -> 178134.88 | R17: =F17/$P17 -> 0.14427 | S17: =G17/$P17 -> 0.017458232 | T17: =H17/$P17 -> 0 | U17: =I17/$P17 -> 0 | V17: =J17/$P17 -> 0.38859633 | W17: =K17/$P17 -> 0.042810706 | X17: =L17/$P17 -> 0 | Y17: =M17/$P17 -> 0.13832215 | ... AA17: =O17/$P17 -> 0.024749785 | AB17: =SUM(R17:AA17) -> 1
A18: 1000431127 | B18: Verizon- VCG H&M Flex - Strate | C18: VZGTTQ00009462 | D18: VCG Flex (Strategically Ready Offers) TQ4164 CTS | E18: Ilango,Parthiban | F18: 37296 | J18: 4200 | M18: 32592 | N18: 40992 | P18: =SUM(F18:O18) -> 115080 | R18: =F18/$P18 -> 0.32408759 | S18: =G18/$P18 -> 0 | T18: =H18/$P18 -> 0 | U18: =I18/$P18 -> 0 | V18: =J18/$P18 -> 0.03649635 | W18: =K18/$P18 -> 0 | X18: =L18/$P18 -> 0 | Y18: =M18/$P18 -> 0.28321168 | ... AA18: =O18/$P18 -> 0 | AB18: =SUM(R18:AA18) -> 1
A19: 1000417402 | B19: Verizon-VCG H&M Flex Elvis HM | C19: VZGTTQ00009564 | D19: VCG Flex (Project Elvis) TQ4164 CTS | E19: Subramanian,Vinu | F19: 134904 | J19: 15456 | M19: 76272 | N19: 86352 | P19: =SUM(F19:O19) -> 312984 | R19: =F19/$P19 -> 0.43102523 | S19: =G19/$P19 -> 0 | T19: =H19/$P19 -> 0 | U19: =I19/$P19 -> 0 | V19: =J19/$P19 -> 0.049382716 | W19: =K19/$P19 -> 0 | X19: =L19/$P19 -> 0 | Y19: =M19/$P19 -> 0.24369297 | ... AA19: =O19/$P19 -> 0 | AB19: =SUM(R19:AA19) -> 1
A20: 1000432850 | B20: VDSI VCG H&M Elvis | C20: VZGTTQ00009682 | D20: VCG_Elvis | E20: JOHN RAJ,Isaiah Ranjith Kumar | F20: 16674.927 | M20: 28518.439 | N20: 4889.3659 | P20: =SUM(F20:O20) -> 50082.732 | R20: =F20/$P20 -> 0.33294763 | S20: =G20/$P20 -> 0 | T20: =H20/$P20 -> 0 | U20: =I20/$P20 -> 0 | V20: =J20/$P20 -> 0 | W20: =K20/$P20 -> 0 | X20: =L20/$P20 -> 0 | Y20: =M20/$P20 -> 0.56942659 | ... AA20: =O20/$P20 -> 0 | AB20: =SUM(R20:AA20) -> 1
A21: 1000445090 | B21: Verizon-VCG H&M Tanglewood-JAN | C21: VZGTTQ00010318 | D21: VCG Flex (Tanglewood) TQ4164 CTS | E21: Mylapore Somasekhar,Jeyakumaar | F21: 182952 | J21: 50106 | L21: 15960 | M21: 77280 | N21: 44520 | P21: =SUM(F21:O21) -> 370818 | R21: =F21/$P21 -> 0.49337411 | S21: =G21/$P21 -> 0 | T21: =H21/$P21 -> 0 | U21: =I21/$P21 -> 0 | V21: =J21/$P21 -> 0.13512289 | W21: =K21/$P21 -> 0 | X21: =L21/$P21 -> 0.043039982 | Y21: =M21/$P21 -> 0.20840412 | ... AA21: =O21/$P21 -> 0 | AB21: =SUM(R21:AA21) -> 1
A22: 1000422748 | B22: Verizon-VCG H&M Flex Commissio | C22: VZGTTQ00010436 | D22: VCG Flex (Sales Performance and commission) TQ4164 CTS | E22: Singh,Shweta | F22: 58800 | P22: =SUM(F22:O22) -> 58800 | R22: =F22/$P22 -> 1 | S22: =G22/$P22 -> 0 | T22: =H22/$P22 -> 0 | U22: =I22/$P22 -> 0 | V22: =J22/$P22 -> 0 | W22: =K22/$P22 -> 0 | X22: =L22/$P22 -> 0 | Y22: =M22/$P22 -> 0 | ... AA22: =O22/$P22 -> 0 | AB22: =SUM(R22:AA22) -> 1
A23: 1000446727 | B23: Verizon-VCG H&M Maslov Instore | C23: VZGTTQ00010544 | D23: VCG Flex (Maslow) TQ4164 CTS | E23: Sriperumbudur Vangeepuram,Rangarajan | F23: 45192 | H23: 16296 | M23: 16296 | P23: =SUM(F23:O23) -> 77784 | R23: =F23/$P23 -> 0.58099352 | S23: =G23/$P23 -> 0 | T23: =H23/$P23 -> 0.20950324 | U23: =I23/$P23 -> 0 | V23: =J23/$P23 -> 0 | W23: =K23/$P23 -> 0 | X23: =L23/$P23 -> 0 | Y23: =M23/$P23 -> 0.20950324 | ... AA23: =O23/$P23 -> 0 | AB23: =SUM(R23:AA23) -> 1
A24: 1000448064 | B24: Verizon-VCG H&M Next Gen Commu | C24: VZGTTQ00010733 | D24: VCG Flex (Next Gen Comms) TQ4164 CTS | E24: Karuppasamy,Saravanan | F24: 0 | G24: 0 | H24: 0 | I24: 0 | J24: 0 | K24: 0 | L24: 0 | M24: 0 | N24: 0 | O24: 0 | P24: 0 | R24: =F24/$P24 -> #DIV/0! | S24: =G24/$P24 -> #DIV/0! | T24: =H24/$P24 -> #DIV/0! | U24: =I24/$P24 -> #DIV/0! | V24: =J24/$P24 -> #DIV/0! | W24: =K24/$P24 -> #DIV/0! | X24: =L24/$P24 -> #DIV/0! | Y24: =M24/$P24 -> #DIV/0! | ... AA24: =O24/$P24 -> #DIV/0! | AB24: =SUM(R24:AA24) -> #DIV/0!
A25: 1000451136 | B25: Verizon-VCG H&M Contract Trans | C25: VZGTTQ00011059 | D25: VCG Flex (XCIO VBG CBRO) CTS TQ4164 | E25: Mothe,Hanmantha Reddy | F25: 19096 | J25: 19696 | N25: 3200 | P25: =SUM(F25:O25) -> 41992 | R25: =F25/$P25 -> 0.45475329 | S25: =G25/$P25 -> 0 | T25: =H25/$P25 -> 0 | U25: =I25/$P25 -> 0 | V25: =J25/$P25 -> 0.46904172 | W25: =K25/$P25 -> 0 | X25: =L25/$P25 -> 0 | Y25: =M25/$P25 -> 0 | ... AA25: =O25/$P25 -> 0 | AB25: =SUM(R25:AA25) -> 1
A26: 1000453836 | B26: Verizon-VCG HM Offer Build-MAR | C26: VZGTTQ00011151 | D26: VCG Flex (Marketing Base Personalization) TQ4164 CTS | E26: Munuswamy,Sheela | F26: 61488 | G26: 4200 | N26: 3000 | P26: =SUM(F26:O26) -> 68688 | R26: =F26/$P26 -> 0.8951782 | S26: =G26/$P26 -> 0.061146052 | T26: =H26/$P26 -> 0 | U26: =I26/$P26 -> 0 | V26: =J26/$P26 -> 0 | W26: =K26/$P26 -> 0 | X26: =L26/$P26 -> 0 | Y26: =M26/$P26 -> 0 | ... AA26: =O26/$P26 -> 0 | AB26: =SUM(R26:AA26) -> 1
A27: Grand Total | F27: =SUM(F3:F26) -> 1810786.5 | G27: =SUM(G3:G26) -> 89216.847 | H27: =SUM(H3:H26) -> 39076.683 | I27: =SUM(I3:I26) -> 3786.1463 | J27: =SUM(J3:J26) -> 647441.15 | K27: =SUM(K3:K26) -> 34835.251 | L27: =SUM(L3:L26) -> 80808 | M27: =SUM(M3:M26) -> 521186.34 | ... P27: =SUM(P3:P26) -> 3728438.3 | R27: =SUM(R3:R26) -> #DIV/0! | S27: =SUM(S3:S26) -> #DIV/0! | T27: =SUM(T3:T26) -> #DIV/0! | U27: =SUM(U3:U26) -> #DIV/0! | V27: =SUM(V3:V26) -> #DIV/0! | W27: =SUM(W3:W26) -> #DIV/0! | X27: =SUM(X3:X26) -> #DIV/0! | Y27: =SUM(Y3:Y26) -> #DIV/0! | ... AB27: =SUM(AB3:AB26) -> #DIV/0!
A29: Cognizant Project ID | B29: Cognizant Project Descriptiom | C29: Verizon Project ID (TQ ID) | D29: Verizon Project Description | F29: ADM | G29: Adobe | H29: AIA | I29: CIS | J29: IDE | K29: IOA | L29: IOT | M29: Pega | N29: QEA | O29: Vertical Core | P29: Grand Total | R29: ADM | S29: Adobe | T29: AIA | U29: CIS | V29: IDE | W29: IOA | X29: IOT | Y29: Pega | Z29: QEA | AA29: Vertical Core | AB29: Grand Total
A30: 1000348365 | B30: VDSI-VCG H&M 1Messaging and Co | C30: VZGTTQ00005360 | D30: ONE MESSAGE AND COMPENSATION APPLICATIONS DEVELOPMENT | E30: Ramasamy,Ravisankar | F30: =F3/$P3 -> 0.75297862 | G30: =G3/$P3 -> 0.24702138 | H30: =H3/$P3 -> 0 | I30: =I3/$P3 -> 0 | J30: =J3/$P3 -> 0 | K30: =K3/$P3 -> 0 | L30: =L3/$P3 -> 0 | M30: =M3/$P3 -> 0 | ... P30: =P3/$P3 -> 1 | R30: =F30/$P30 -> 0.75297862 | S30: =G30/$P30 -> 0.24702138 | T30: =H30/$P30 -> 0 | U30: =I30/$P30 -> 0 | V30: =J30/$P30 -> 0 | W30: =K30/$P30 -> 0 | X30: =L30/$P30 -> 0 | Y30: =M30/$P30 -> 0 | ... AB30: =P30/$P30 -> 1
A31: 1000415076 | B31: Verizon-VCG H&M Flex FPP TQ835 | C31: VZGTTQ00008351 | D31: VCG Flex 2024 (FPP) CTS TQ4164 | E31: Ilango,Parthiban | F31: =F4/$P4 -> 0.35336538 | G31: =G4/$P4 -> 0 | H31: =H4/$P4 -> 0 | I31: =I4/$P4 -> 0 | J31: =J4/$P4 -> 0.030048077 | K31: =K4/$P4 -> 0 | L31: =L4/$P4 -> 0.11658654 | M31: =M4/$P4 -> 0.40985577 | ... P31: =P4/$P4 -> 1 | R31: =F31/$P31 -> 0.35336538 | S31: =G31/$P31 -> 0 | T31: =H31/$P31 -> 0 | U31: =I31/$P31 -> 0 | V31: =J31/$P31 -> 0.030048077 | W31: =K31/$P31 -> 0 | X31: =L31/$P31 -> 0.11658654 | Y31: =M31/$P31 -> 0.40985577 | ... AB31: =P31/$P31 -> 1
A33: 1000410707 | B33: Verizon-VCG H&M Flex ACT Dig H | C33: VZGTTQ00008374 | D33: VCG Flex (5G FWA Digital Experience) TQ4164 CTS | E33: Jayaprakash,Arun Kumar | F33: =F5/$P5 -> 0.51764706 | G33: =G5/$P5 -> 0 | H33: =H5/$P5 -> 0 | I33: =I5/$P5 -> 0 | J33: =J5/$P5 -> 0.24705882 | K33: =K5/$P5 -> 0 | L33: =L5/$P5 -> 0 | M33: =M5/$P5 -> 0 | ... P33: =P5/$P5 -> 1 | R33: =F33/$P33 -> 0.51764706 | S33: =G33/$P33 -> 0 | T33: =H33/$P33 -> 0 | U33: =I33/$P33 -> 0 | V33: =J33/$P33 -> 0.24705882 | W33: =K33/$P33 -> 0 | X33: =L33/$P33 -> 0 | Y33: =M33/$P33 -> 0 | ... AB33: =P33/$P33 -> 1
A34: 1000410706 | B34: Verizon-VCG H&M Flex ACT 5G Pr | C34: VZGTTQ00008385 | D34: VCG Flex 2024 (5G FWA Consumer Products) TQ4164 CTS | E34: Mylapore Somasekhar,Jeyakumaar | F34: =F6/$P6 -> 0.7080292 | G34: =G6/$P6 -> 0 | H34: =H6/$P6 -> 0 | I34: =I6/$P6 -> 0 | J34: =J6/$P6 -> 0.2919708 | K34: =K6/$P6 -> 0 | L34: =L6/$P6 -> 0 | M34: =M6/$P6 -> 0 | ... P34: =P6/$P6 -> 1 | R34: =F34/$P34 -> 0.7080292 | S34: =G34/$P34 -> 0 | T34: =H34/$P34 -> 0 | U34: =I34/$P34 -> 0 | V34: =J34/$P34 -> 0.2919708 | W34: =K34/$P34 -> 0 | X34: =L34/$P34 -> 0 | Y34: =M34/$P34 -> 0 | ... AB34: =P34/$P34 -> 1
A35: 1000416318 | B35: Verizon-VCG H&M Flex CPI EPC T | C35: VZGTTQ00008473 | D35: VCG Flex 2024 (CPI_EPC_PRE_DEEPSHIKHA) TQ4164 CTS | E35: Ilango,Parthiban | F35: =F7/$P7 -> 0.93374317 | G35: =G7/$P7 -> 0 | H35: =H7/$P7 -> 0 | I35: =I7/$P7 -> 0 | J35: =J7/$P7 -> 0.066256831 | K35: =K7/$P7 -> 0 | L35: =L7/$P7 -> 0 | M35: =M7/$P7 -> 0 | ... P35: =P7/$P7 -> 1 | R35: =F35/$P35 -> 0.93374317 | S35: =G35/$P35 -> 0 | T35: =H35/$P35 -> 0 | U35: =I35/$P35 -> 0 | V35: =J35/$P35 -> 0.066256831 | W35: =K35/$P35 -> 0 | X35: =L35/$P35 -> 0 | Y35: =M35/$P35 -> 0 | ... AB35: =P35/$P35 -> 1
A36: 1000417403 | B36: Verizon-VCG H&M Flex DigiOps - | C36: VZGTTQ00008593 | D36: VCG Flex (Digital Ops Enabler) TQ4164 CTS | E36: Jain,Atik | F36: =F8/$P8 -> 0 | G36: =G8/$P8 -> 1 | H36: =H8/$P8 -> 0 | I36: =I8/$P8 -> 0 | J36: =J8/$P8 -> 0 | K36: =K8/$P8 -> 0 | L36: =L8/$P8 -> 0 | M36: =M8/$P8 -> 0 | ... P36: =P8/$P8 -> 1 | R36: =F36/$P36 -> 0 | S36: =G36/$P36 -> 1 | T36: =H36/$P36 -> 0 | U36: =I36/$P36 -> 0 | V36: =J36/$P36 -> 0 | W36: =K36/$P36 -> 0 | X36: =L36/$P36 -> 0 | Y36: =M36/$P36 -> 0 | ... AB36: =P36/$P36 -> 1
A37: 1000412773 | B37: Verizon-VCG H&M Flex Mobile Of | C37: VZGTTQ00008730 | D37: VCG Flex (Mobile Offers Post Paid) TQ4164 CTS | E37: Vadlamudi,Vijay Kumar | F37: =F9/$P9 -> 0.49852449 | G37: =G9/$P9 -> 0 | H37: =H9/$P9 -> 0 | I37: =I9/$P9 -> 0 | J37: =J9/$P9 -> 0.22545741 | K37: =K9/$P9 -> 0.0043281527 | L37: =L9/$P9 -> 0.056856187 | M37: =M9/$P9 -> 0.1558135 | ... P37: =P9/$P9 -> 1 | R37: =F37/$P37 -> 0.49852449 | S37: =G37/$P37 -> 0 | T37: =H37/$P37 -> 0 | U37: =I37/$P37 -> 0 | V37: =J37/$P37 -> 0.22545741 | W37: =K37/$P37 -> 0.0043281527 | X37: =L37/$P37 -> 0.056856187 | Y37: =M37/$P37 -> 0.1558135 | ... AB37: =P37/$P37 -> 1
A38: 1000422748 | B38: Verizon-VCG H&M Flex Commissio | C38: VZGTTQ00008929 | D38: VCG Flex (Commissions) TQ4164 CTS | E38: Singh,Shweta | F38: =F10/$P10 -> 0.94175914 | G38: =G10/$P10 -> 0 | H38: =H10/$P10 -> 0.058240858 | I38: =I10/$P10 -> 0 | J38: =J10/$P10 -> 0 | K38: =K10/$P10 -> 0 | L38: =L10/$P10 -> 0 | M38: =M10/$P10 -> 0 | ... P38: =P10/$P10 -> 1 | R38: =F38/$P38 -> 0.94175914 | S38: =G38/$P38 -> 0 | T38: =H38/$P38 -> 0.058240858 | U38: =I38/$P38 -> 0 | V38: =J38/$P38 -> 0 | W38: =K38/$P38 -> 0 | X38: =L38/$P38 -> 0 | Y38: =M38/$P38 -> 0 | ... AB38: =P38/$P38 -> 1
A39: 1000422753 | B39: Verizon-VCG H&M Flex Home APP | C39: VZGTTQ00008947 | D39: VCG Flex (Home App) TQ4164 CTS | E39: Mylapore Somasekhar,Jeyakumaar | F39: =F11/$P11 -> 0.24234694 | G39: =G11/$P11 -> 0 | H39: =H11/$P11 -> 0 | I39: =I11/$P11 -> 0 | J39: =J11/$P11 -> 0 | K39: =K11/$P11 -> 0 | L39: =L11/$P11 -> 0 | M39: =M11/$P11 -> 0.29336735 | ... P39: =P11/$P11 -> 1 | R39: =F39/$P39 -> 0.24234694 | S39: =G39/$P39 -> 0 | T39: =H39/$P39 -> 0 | U39: =I39/$P39 -> 0 | V39: =J39/$P39 -> 0 | W39: =K39/$P39 -> 0 | X39: =L39/$P39 -> 0 | Y39: =M39/$P39 -> 0.29336735 | ... AB39: =P39/$P39 -> 1
A40: 1000416320 | B40: Verizon-VCG H&M Flex oneMessag | C40: VZGTTQ00009022 | D40: VCG Flex (VBG One Message AEM Migration) TQ4164 CTS | E40: Chennam,Sujana Sree | F40: =F12/$P12 -> 0.78419072 | G40: =G12/$P12 -> 0 | H40: =H12/$P12 -> 0 | I40: =I12/$P12 -> 0 | J40: =J12/$P12 -> 0 | K40: =K12/$P12 -> 0 | L40: =L12/$P12 -> 0 | M40: =M12/$P12 -> 0.1217064 | ... P40: =P12/$P12 -> 1 | R40: =F40/$P40 -> 0.78419072 | S40: =G40/$P40 -> 0 | T40: =H40/$P40 -> 0 | U40: =I40/$P40 -> 0 | V40: =J40/$P40 -> 0 | W40: =K40/$P40 -> 0 | X40: =L40/$P40 -> 0 | Y40: =M40/$P40 -> 0.1217064 | ... AB40: =P40/$P40 -> 1
A41: 1000425394 | B41: VDSI VCG H&M Knowledge Orchest | C41: VZGTTQ00009155 | D41: VCG Knowledge Orchestration | E41: Thangavadivel,Sharathkumar | F41: =F13/$P13 -> 0.21172658 | G41: =G13/$P13 -> 0.58950969 | H41: =H13/$P13 -> 0 | I41: =I13/$P13 -> 0 | J41: =J13/$P13 -> 0 | K41: =K13/$P13 -> 0 | L41: =L13/$P13 -> 0 | M41: =M13/$P13 -> 0 | ... P41: =P13/$P13 -> 1 | R41: =F41/$P41 -> 0.21172658 | S41: =G41/$P41 -> 0.58950969 | T41: =H41/$P41 -> 0 | U41: =I41/$P41 -> 0 | V41: =J41/$P41 -> 0 | W41: =K41/$P41 -> 0 | X41: =L41/$P41 -> 0 | Y41: =M41/$P41 -> 0 | ... AB41: =P41/$P41 -> 1
A42: 1000425175 | B42: VDSI VCG H&M IFE and BCP | C42: VZGTTQ00009158 | D42: VCG IFE and BCP | E42: P,Arunkumar | F42: =F14/$P14 -> 0.51838748 | G42: =G14/$P14 -> 0 | H42: =H14/$P14 -> 0 | I42: =I14/$P14 -> 0 | J42: =J14/$P14 -> 0.48161252 | K42: =K14/$P14 -> 0 | L42: =L14/$P14 -> 0 | M42: =M14/$P14 -> 0 | ... P42: =P14/$P14 -> 1 | R42: =F42/$P42 -> 0.51838748 | S42: =G42/$P42 -> 0 | T42: =H42/$P42 -> 0 | U42: =I42/$P42 -> 0 | V42: =J42/$P42 -> 0.48161252 | W42: =K42/$P42 -> 0 | X42: =L42/$P42 -> 0 | Y42: =M42/$P42 -> 0 | ... AB42: =P42/$P42 -> 1
...

Sheet August RFR
J1: 2025 - Q3 - Quarter | M1: 2025 - Q4 - Quarter
A2: EmpID | B2: Name | C2: Location | D2: ACT/PCT | E2: Skill Set | F2: Verizon Level Mapping | G2: Cognizant Designation | H2: Hourly Rate ($) | I2: Monthly Rate ($) | J2: 45839 | K2: 45870 | L2: 45901 | M2: 45931 | N2: 45962 | O2: 45992 | P2: New Flex 2.0 ESA ID | Q2: New Flex 2.0 ESA Project Description | R2: New TQ ID | S2: New Verizon TQ Descroption | T2: Service Line
A3: 421594 | B3: Sunil Kumar Velaga | C3: Onshore Supplier Location | D3: ACT 238 | E3: Java Springboot Microservices SpringReactive | F3: Level 3 - Premium Skills | G3: M | H3: 96.56 | I3: 16222.08 | J3: 16222.08 | K3: 16222.08 | L3: 16222.08 | M3: 16222.08 | N3: 16222.08 | O3: 16222.08 | P3: 1000459566 | Q3: Verizon VCG Flex 2.0 HM Strate | R3: VZGTTQ00012012 | S3: VCG Flex (Strategically Ready Offers) TQ9703 CTS | T3: ADM
A4: 630134 | B4: Paramasivam, Arasakumar | C4: Onshore Supplier Location | D4: ACT 238 | E4: QA Analyst | F4: Level 3 - Standard Skills | G4: M | H4: 91.9 | I4: 15439.2 | J4: 15439.2 | K4: 15439.2 | L4: 15439.2 | M4: 15439.2 | N4: 15439.2 | O4: 15439.2 | P4: 1000459566 | Q4: Verizon VCG Flex 2.0 HM Strate | R4: VZGTTQ00012013 | S4: VCG Flex (Strategically Ready Offers) TQ9703 CTS | T4: QEA
A5: 955164 | B5: Gomez,Giovanni | C5: Onshore Supplier Location | D5: ACT 238 | E5: QA Analyst | F5: Level 2 - Standard Skills | G5: A | H5: 77 | I5: 12936 | J5: 12936 | K5: 12936 | L5: 12936 | M5: 12936 | N5: 12936 | O5: 12936 | P5: 1000459566 | Q5: Verizon VCG Flex 2.0 HM Strate | R5: VZGTTQ00012014 | S5: VCG Flex (Strategically Ready Offers) TQ9703 CTS | T5: QEA
A6: 2387626 | B6: Kamna,Bhuwan | C6: India | D6: ACT 238 | E6: Java Springboot Microservices SpringReactive | F6: Level 3 - Premium Skills | G6: M | H6: 24.8 | I6: 4687.2 | J6: 4687.2 | K6: 4687.2 | L6: 4687.2 | M6: 4687.2 | N6: 4687.2 | O6: 4687.2 | P6: 1000459566 | Q6: Verizon VCG Flex 2.0 HM Strate | R6: VZGTTQ00012015 | S6: VCG Flex (Strategically Ready Offers) TQ9703 CTS | T6: ADM
A7: 2397654 | B7: Ajey Srinivasu | C7: India | D7: ACT 238 | E7: Java Springboot Microservices SpringReactive | F7: Level 2 - Premium Skills | G7: Cont | H7: 21.3 | I7: 4025.7 | J7: 4025.7 | K7: 4025.7 | L7: 4025.7 | M7: 4025.7 | N7: 4025.7 | O7: 4025.7 | P7: 1000459566 | Q7: Verizon VCG Flex 2.0 HM Strate | R7: VZGTTQ00012016 | S7: VCG Flex (Strategically Ready Offers) TQ9703 CTS | T7: IDE
A8: 2089658 | B8: Lalkumar P | C8: India | D8: ACT 238 | E8: QA Analyst | F8: Level 2 - Standard Skills | G8: A | H8: 20 | I8: 3780 | J8: 3780 | K8: 3780 | L8: 3780 | M8: 3780 | N8: 3780 | O8: 3780 | P8: 1000459566 | Q8: Verizon VCG Flex 2.0 HM Strate | R8: VZGTTQ00012017 | S8: VCG Flex (Strategically Ready Offers) TQ9703 CTS | T8: QEA
A9: 912357 | B9: Shubhada Revanna | C9: India | D9: ACT 238 | E9: QA Analyst | F9: Level 2 - Standard Skills | G9: A | H9: 20 | I9: 3780 | J9: 3780 | K9: 3780 | L9: 3780 | M9: 3780 | N9: 3780 | O9: 3780 | P9: 1000459566 | Q9: Verizon VCG Flex 2.0 HM Strate | R9: VZGTTQ00012018 | S9: VCG Flex (Strategically Ready Offers) TQ9703 CTS | T9: QEA
A10: 783316 | B10: Mounika Bireddy | C10: India | D10: ACT 238 | E10: Java Springboot Microservices SpringReactive | F10: Level 3 - Premium Skills | G10: SA | H10: 24.8 | I10: 4687.2 | J10: 4687.2 | K10: 4687.2 | L10: 4687.2 | M10: 4687.2 | N10: 4687.2 | O10: 4687.2 | P10: 1000459566 | Q10: Verizon VCG Flex 2.0 HM Strate | R10: VZGTTQ00012019 | S10: VCG Flex (Strategically Ready Offers) TQ9703 CTS | T10: IDE
A11: 2345201 | B11: Narina, Sai Srikanth | C11: Onshore Supplier Location | D11: ACT 238 | E11: PEGA | F11: Level 3 - Niche Skills | G11: Cont | H11: 98.21 | I11: 18561.69 | J11: 16499.28 | K11: 16499.28 | L11: 16499.28 | M11: 16499.28 | N11: 16499.28 | O11: 16499.28 | P11: 1000459566 | Q11: Verizon VCG Flex 2.0 HM Strate | R11: VZGTTQ00012020 | S11: VCG Flex (Strategically Ready Offers) TQ9703 CTS | T11: EPS
A12: 2138272 | B12: S, Chithra | C12: India | D12: ACT 238 | E12: Release Train Engineer | F12: Level 3 - Standard Skills | G12: SA | H12: 22.9 | I12: 4328.1 | J12: 4328.1 | K12: 4328.1 | L12: 4328.1 | M12: 4328.1 | N12: 4328.1 | O12: 4328.1 | P12: 1000459566 | Q12: Verizon VCG Flex 2.0 HM Strate | R12: VZGTTQ00012021 | S12: VCG Flex (Strategically Ready Offers) TQ9703 CTS | T12: IOA
A13: 2088900 | B13: Naveen Durai | C13: Onshore Supplier Location | D13: ACT 238 | E13: PEGA | F13: Level 3 - Niche Skills | G13: Cont | H13: 98.21 | I13: 16499.28 | J13: 16499.28 | K13: 16499.28 | L13: 16499.28 | M13: 16499.28 | N13: 16499.28 | O13: 16499.28 | P13: 1000459566 | Q13: Verizon VCG Flex 2.0 HM Strate | R13: VZGTTQ00012022 | S13: VCG Flex (Strategically Ready Offers) TQ9703 CTS | T13: EPS
A14: 527576 | B14: Pradeep Kumar Selvaraj | C14: India | D14: ACT 238 | E14: Java Springboot Microservices SpringReactive | F14: Level 3 - Premium Skills | G14: SA | H14: 24.8 | I14: 4687.2 | J14: 4687.2 | K14: 4687.2 | L14: 4687.2 | M14: 4687.2 | N14: 4687.2 | O14: 4687.2 | P14: 1000459566 | Q14: Verizon VCG Flex 2.0 HM Strate | R14: VZGTTQ00012023 | S14: VCG Flex (Strategically Ready Offers) TQ9703 CTS | T14: ADM
A15: 2405817 | B15: Hariharasudan | C15: India | D15: ACT 238 | E15: Java Springboot Microservices SpringReactive | F15: Level 3 - Premium Skills | G15: M | H15: 24.8 | I15: 4687.2 | J15: 4687.2 | K15: 4687.2 | L15: 4687.2 | M15: 4687.2 | N15: 4687.2 | O15: 4687.2 | P15: 1000459566 | Q15: Verizon VCG Flex 2.0 HM Strate | R15: VZGTTQ00012024 | S15: VCG Flex (Strategically Ready Offers) TQ9703 CTS | T15: ADM
A16: TBD | B16: TBD | C16: Onshore Supplier Location | D16: ACT 238 | E16: PEGA | F16: Level 3 - Niche Skills | G16: M | H16: 98.21 | I16: 16499.28 | J16: 16499.28 | K16: 16499.28 | L16: 16499.28 | M16: 16499.28 | N16: 16499.28 | O16: 16499.28 | P16: 1000459566 | Q16: Verizon VCG Flex 2.0 HM Strate | R16: VZGTTQ00012025 | S16: VCG Flex (Strategically Ready Offers) TQ9703 CTS | T16: ADM
A17: 973537 | B17: Anitha Nalluri (50%) | C17: Onshore Supplier Location | D17: PCT 248 | E17: Java Springboot Microservices SpringReactive | F17: Level 3 - Premium Skills | G17: M | H17: 96.56 | I17: 16222.08 | J17: 16222.08 | K17: 16222.08 | L17: 16222.08 | M17: 16222.08 | N17: 16222.08 | O17: 16222.08 | P17: 1000456939 | Q17: Verizon-VCG HM Flex2.0 CPI EPC | R17: VZGTTQ00011503 | S17: VCG Flex 2024 (CPI_EPC_PRE_DEEPSHIKHA) TQ4164 CTS - 2025 | T17: ADM
A18: 953609 | B18: Deepika Gudise | C18: Onshore Supplier Location | D18: PCT 248 | E18: Scrum Master | F18: Level 3 - Standard Skills | G18: SA | H18: 91.9 | I18: 15439.2 | J18: 15439.2 | K18: 15439.2 | L18: 15439.2 | M18: 15439.2 | N18: 15439.2 | O18: 15439.2 | P18: 1000456939 | Q18: Verizon-VCG HM Flex2.0 CPI EPC | R18: VZGTTQ00011504 | S18: VCG Flex 2024 (CPI_EPC_PRE_DEEPSHIKHA) TQ4164 CTS - 2026 | T18: ADM
A19: 973456 | B19: Mikail Krochta (50%) | C19: Onshore Supplier Location | D19: PCT 248 | E19: Java Springboot Microservices SpringReactive | F19: Level 2 - Premium Skills | G19: A | H19: 82.05 | I19: 13784.4 | J19: 13784.4 | K19: 13784.4 | L19: 13784.4 | M19: 13784.4 | N19: 13784.4 | O19: 13784.4 | P19: 1000456939 | Q19: Verizon-VCG HM Flex2.0 CPI EPC | R19: VZGTTQ00011505 | S19: VCG Flex 2024 (CPI_EPC_PRE_DEEPSHIKHA) TQ4164 CTS - 2027 | T19: ADM
A20: 978430 | B20: Prasantha Deva (50%) | C20: Onshore Supplier Location | D20: PCT 248 | E20: Java Springboot Microservices SpringReactive | F20: Level 3 - Premium Skills | G20: M | H20: 96.56 | I20: 16222.08 | J20: 16222.08 | K20: 16222.08 | L20: 16222.08 | M20: 16222.08 | N20: 16222.08 | O20: 16222.08 | P20: 1000456939 | Q20: Verizon-VCG HM Flex2.0 CPI EPC | R20: VZGTTQ00011506 | S20: VCG Flex 2024 (CPI_EPC_PRE_DEEPSHIKHA) TQ4164 CTS - 2028 | T20: ADM
A21: 968349 | B21: Guzzi,Kathleen | C21: Onshore Supplier Location | D21: PCT 247 | E21: Business Analyst | F21: Level 4 - Expert Skills | G21: M | H21: 128 | I21: 21504 | J21: 21504 | K21: 21504 | L21: 21504 | M21: 21504 | N21: 21504 | O21: 21504 | P21: 1000456939 | Q21: Verizon-VCG HM Flex2.0 CPI EPC | R21: VZGTTQ00011507 | S21: VCG Flex 2024 (CPI_EPC_PRE_DEEPSHIKHA) TQ4164 CTS - 2029 | T21: ADM
A22: 952025 | B22: Vicki Pflughaupt | C22: Onshore Supplier Location | D22: PCT 247 | E22: Business Analyst | F22: Level 4 - Expert Skills | G22: SA | H22: 128 | I22: 21504 | J22: 21504 | K22: 21504 | L22: 21504 | M22: 21504 | N22: 21504 | O22: 21504 | P22: 1000456939 | Q22: Verizon-VCG HM Flex2.0 CPI EPC | R22: VZGTTQ00011508 | S22: VCG Flex 2024 (CPI_EPC_PRE_DEEPSHIKHA) TQ4164 CTS - 2030 | T22: ADM
A23: 758494 | B23: PremChand Maddineni (50%) | C23: Onshore Supplier Location | D23: PCT 246 | E23: Java Springboot Microservices SpringReactive | F23: Level 3 - Premium Skills | G23: SA | H23: 96.56 | I23: 16222.08 | J23: 16222.08 | K23: 16222.08 | L23: 16222.08 | M23: 16222.08 | N23: 16222.08 | O23: 16222.08 | P23: 1000456939 | Q23: Verizon-VCG HM Flex2.0 CPI EPC | R23: VZGTTQ00011509 | S23: VCG Flex 2024 (CPI_EPC_PRE_DEEPSHIKHA) TQ4164 CTS - 2031 | T23: ADM
A24: 969710 | B24: Bola Adebanwo | C24: Onshore Supplier Location | D24: PCT 246 | E24: Java Springboot Microservices SpringReactive | F24: Level 4 - Expert Skills | G24: A | H24: 128 | I24: 21504 | J24: 21504 | K24: 21504 | L24: 21504 | M24: 21504 | N24: 21504 | O24: 21504 | P24: 1000456939 | Q24: Verizon-VCG HM Flex2.0 CPI EPC | R24: VZGTTQ00011510 | S24: VCG Flex 2024 (CPI_EPC_PRE_DEEPSHIKHA) TQ4164 CTS - 2032 | T24: ADM
A25: 970927 | B25: Stefi Gomez | C25: Onshore Supplier Location | D25: PCT 054 | E25: Java Springboot Microservices SpringReactive | F25: Level 3 - Premium Skills | G25: SA | H25: 96.56 | I25: 16222.08 | J25: 16222.08 | K25: 16222.08 | L25: 16222.08 | M25: 16222.08 | N25: 16222.08 | O25: 16222.08 | P25: 1000456939 | Q25: Verizon-VCG HM Flex2.0 CPI EPC | R25: VZGTTQ00011511 | S25: VCG Flex 2024 (CPI_EPC_PRE_DEEPSHIKHA) TQ4164 CTS - 2033 | T25: ADM
A26: 968444 | B26: Suzanne Spadling | C26: Onshore Supplier Location | D26: PCT 246 | E26: Business Analyst | F26: Level 4 - Expert Skills | G26: M | H26: 128 | I26: 21504 | J26: 21504 | K26: 21504 | L26: 21504 | M26: 21504 | N26: 21504 | O26: 21504 | P26: 1000456939 | Q26: Verizon-VCG HM Flex2.0 CPI EPC | R26: VZGTTQ00011512 | S26: VCG Flex 2024 (CPI_EPC_PRE_DEEPSHIKHA) TQ4164 CTS - 2034 | T26: ADM
A27: 970667 | B27: Diane Hammer | C27: Onshore Supplier Location | D27: PCT 247 | E27: Business Analyst | F27: Level 4 - Expert Skills | G27: SA | H27: 128 | I27: 21504 | J27: 21504 | K27: 21504 | L27: 21504 | M27: 21504 | N27: 21504 | O27: 21504 | P27: 1000456939 | Q27: Verizon-VCG HM Flex2.0 CPI EPC | R27: VZGTTQ00011513 | S27: VCG Flex 2024 (CPI_EPC_PRE_DEEPSHIKHA) TQ4164 CTS - 2035 | T27: ADM
